Workbook

Sheet cover
A4: A PROJECT ON
A6: TATA CONSULTANCY SERVICES
A8: FY2026 FP&A MODEL
A10: Financial Analysis, Forecasting & Management Insights
B14: HISTORICAL PERIOD | E14: FORECAST PERIOD
B15: FY2021 – FY2025 | E15: FY2026
A20: PREPARED BY
A21: JISHNU.P
A23: Financial Performance | Forecasting | Variance Analysis
A24: Working Capital | Cash Flow | Management Insights
A25: "This model is prepared for FP&A analysis and educational purposes using publicly available information. FY2026 figures are independently prepared forecasts and do not represent official TCS guidance or internal forecasts. No confidential company data has been used. Reasonable care has been taken in preparing the model; however, assumptions, estimates or unintentional errors may exist, and actual results may differ from the forecast."
A27: FY2026 Forecast • Management Planning & Decision Support

Sheet dashboard
A1: TCS FY2026 FP&A DASHBOARD
A2: Metric | B2: FY2021 | C2: FY2022 | D2: FY2023 | E2: FY2024 | F2: FY2025 | G2: FY2026
A3: REVENUE | B3: ='FINANCIAL ANALYSIS'!B4 -> 164177 | C3: ='FINANCIAL ANALYSIS'!C4 -> 191754 | D3: ='FINANCIAL ANALYSIS'!D4 -> 225458 | E3: ='FINANCIAL ANALYSIS'!E4 -> 240893 | F3: ='FINANCIAL ANALYSIS'!F4 -> 255324 | G3: ='FINANCIAL FORECAST'!C4 -> 271715.8
A4: EXPENSE | B4: ='FINANCIAL ANALYSIS'!B22 -> 122333 | C4: ='FINANCIAL ANALYSIS'!C22 -> 144085 | D4: ='FINANCIAL ANALYSIS'!D22 -> 172000 | E4: ='FINANCIAL ANALYSIS'!E22 -> 182360 | F4: ='FINANCIAL ANALYSIS'!F22 -> 193955 | G4: =SUM('FINANCIAL FORECAST'!C5:C9) -> 203699.7
A5: EBIT | B5: ='FINANCIAL ANALYSIS'!B30 -> 44397 | C5: ='FINANCIAL ANALYSIS'!C30 -> 52471 | D5: ='FINANCIAL ANALYSIS'!D30 -> 57686 | E5: ='FINANCIAL ANALYSIS'!E30 -> 62775 | F5: ='FINANCIAL ANALYSIS'!F30 -> 66127 | G5: ='FINANCIAL FORECAST'!C10 -> 68903.932
A6: NET PROF | B6: ='FINANCIAL ANALYSIS'!B33 -> 32562 | C6: ='FINANCIAL ANALYSIS'!C33 -> 38449 | D6: ='FINANCIAL ANALYSIS'!D33 -> 42303 | E6: ='FINANCIAL ANALYSIS'!E33 -> 46099 | F6: ='FINANCIAL ANALYSIS'!F33 -> 48797 | G6: ='FINANCIAL FORECAST'!C13 -> 50629.069
A7: OCF | B7: ='FINANCIAL ANALYSIS'!B60 -> 38802 | C7: ='FINANCIAL ANALYSIS'!C60 -> 39949 | D7: ='FINANCIAL ANALYSIS'!D60 -> 41965 | E7: ='FINANCIAL ANALYSIS'!E60 -> 44338 | F7: ='FINANCIAL ANALYSIS'!F60 -> 48908 | G7: ='FINANCIAL FORECAST'!C26 -> 57553.574
A8: OWC | B8: ='FINANCIAL ANALYSIS'!B53 -> 25152 | C8: ='FINANCIAL ANALYSIS'!C53 -> 30130 | D8: ='FINANCIAL ANALYSIS'!D53 -> 35596 | E8: ='FINANCIAL ANALYSIS'!E53 -> 39956 | F8: ='FINANCIAL ANALYSIS'!F53 -> 41109 | G8: ='FINANCIAL FORECAST'!C20 -> 39763.032
A9: FCF | B9: ='FINANCIAL ANALYSIS'!B64 -> 35727 | C9: ='FINANCIAL ANALYSIS'!C64 -> 36969 | D9: ='FINANCIAL ANALYSIS'!D64 -> 39078 | E9: ='FINANCIAL ANALYSIS'!E64 -> 41694 | F9: ='FINANCIAL ANALYSIS'!F64 -> 45047 | G9: ='FINANCIAL FORECAST'!C28 -> 54007.983

Sheet HISTORICAL FINANCIALS
A1: TATA CONSULTANCY SERVICES FINANCIAL STATEMENTS FY2021-25
A3: (All figures in ₹ Crore)
A4: PARTICULARS | B4: FY 2021 | C4: FY 2022 | D4: FY 2023 | E4: FY 2024 | F4: FY 2025
A5: CONSOLIDATED STATEMENT OF PROFIT AND LOSS
A6: REVENUE
A7: revenue from operations | B7: 164177 | C7: 191754 | D7: 225458 | E7: 240893 | F7: 255324
A8: other income | B8: 3134 | C8: 4018 | D8: 3449 | E8: 4422 | F8: 3962
A9: Total Revenue | B9: =SUM(B7:B8) -> 167311 | C9: =SUM(C7:C8) -> 195772 | D9: =SUM(D7:D8) -> 228907 | E9: =SUM(E7:E8) -> 245315 | F9: =F7+F8 -> 259286
A10: EXPENSES
A11: employee benefit expense | B11: 91814 | C11: 107554 | D11: 127522 | E11: 140131 | F11: 145788
A12: Cost of Equipment & Software Licences | B12: 1462 | C12: 1163 | D12: 1881 | E12: 3702 | F12: 11648
A13: finance costs | B13: 637 | C13: 784 | D13: 779 | E13: 778 | F13: 796
A14: depreciation&amortization | B14: 4065 | C14: 4604 | D14: 5022 | E14: 4985 | F14: 5242
A15: other operating expenses | B15: 24355 | C15: 29980 | D15: 36796 | E15: 32764 | F15: 30481
A16: Total Expenses | B16: =SUM(B11:B15) -> 122333 | C16: =SUM(C11:C15) -> 144085 | D16: =SUM(D11:D15) -> 172000 | E16: =SUM(E11:E15) -> 182360 | F16: =SUM(F11:F15) -> 193955
A17: PROFITABILITY
A18: Profit Before Exceptional Item and Tax | B18: =B9-B16 -> 44978 | C18: =C9-C16 -> 51687 | D18: =D9-D16 -> 56907 | E18: =E9-E16 -> 62955 | F18: =F9-F16 -> 65331
A19: Exceptional Item | B19: 1218 | C19: 0 | D19: 0 | E19: 958 | F19: 0
A20: profit before tax | B20: =B18-B19 -> 43760 | C20: =C18-C19 -> 51687 | D20: =D18-D19 -> 56907 | E20: =E18-E19 -> 61997 | F20: =F18-F19 -> 65331
A21: Tax Expense | B21: 11198 | C21: 13238 | D21: 14604 | E21: 15898 | F21: 16534
A22: Profit for the Year | B22: =B20-B21 -> 32562 | C22: =C20-C21 -> 38449 | D22: =D20-D21 -> 42303 | E22: =E20-E21 -> 46099 | F22: =F20-F21 -> 48797
A25: CONSOLIDATED STATEMENT OF CASH FLOWS
A26: CASH FLOWS FROM OPERATING ACTIVITIES ACTIVITIES
A27: Profit for the year Adjustments for | B27: 32562 | C27: 38449 | D27: 42303 | E27: 46099 | F27: 48797
A28: Depreciation and amortisation expense | B28: 4065 | C28: 4604 | D28: 5022 | E28: 4985 | F28: 5242
A29: Bad debts and advances written off, allowance for doubtful trade receivables and advances (net) | B29: 201 | C29: 135 | D29: 140 | E29: 114 | F29: 128
A30: Provision towards legal claim | B30: 1218 | C30: 0 | D30: 0 | E30: 0 | F30: 0
A31: Tax expense | B31: 11198 | C31: 13238 | D31: 14604 | E31: 15898 | F31: 16534
A32: Net gain on lease modification | B32: -100 | C32: -7 | D32: 2 | E32: -7 | F32: -15
A33: Net loss on sub-lease | B33: 0 | C33: 9 | D33: 0 | E33: 0 | F33: 0
A34: Unrealised foreign exchange gain | B34: -21 | C34: -120 | D34: -189 | E34: -17 | F34: -1
A35: Net gain on disposal of property, plant and equipment | B35: -13 | C35: -23 | D35: -26 | E35: -7 | F35: -20
A36: Net gain on disposal / fair valuation of investments | B36: -204 | C36: -198 | D36: -224 | E36: -312 | F36: -269
A37: Interest income | B37: -2504 | C37: -2663 | D37: -3248 | E37: -3781 | F37: -3296
A38: Dividend income | B38: -8 | C38: -4 | D38: -15 | E38: -41 | F38: -43
A39: Finance costs | B39: 637 | C39: 784 | D39: 779 | E39: 778 | F39: 796
A40: Operating profit before working capital changes Net change in | B40: =SUM(B27:B39) -> 47031 | C40: =SUM(C27:C39) -> 54204 | D40: =SUM(D27:D39) -> 59148 | E40: =SUM(E27:E39) -> 63709 | F40: =SUM(F27:F39) -> 67853
A41: inventories | B41: -3 | C41: -12 | D41: -8 | E41: 0 | F41: 7
A42: Trade receivables
A43: Billed | B43: 1260 | C43: -4210 | D43: -6501 | E43: -3327 | F43: -5519
...

Sheet FINANCIAL ANALYSIS
A1: TATA CONSULTANCY SERVICES FINANCIAL ANALYSIS FY2021-25
A2: REVENUE ANALYSIS
A3: Particulars | B3: FY2021 | C3: FY2022 | D3: FY2023 | E3: FY2024 | F3: FY2025
A4: Revenue from Operations | B4: ='HISTORICAL FINANCIALS'!B7 -> 164177 | C4: ='HISTORICAL FINANCIALS'!C7 -> 191754 | D4: ='HISTORICAL FINANCIALS'!D7 -> 225458 | E4: ='HISTORICAL FINANCIALS'!E7 -> 240893 | F4: ='HISTORICAL FINANCIALS'!F7 -> 255324
A5: YoY Revenue Growth % | B5: — | C5: =C4/B4-1 -> 0.16797115 | D5: =D4/C4-1 -> 0.17576687 | E5: =E4/D4-1 -> 0.068460645 | F5: =F4/E4-1 -> 0.059906265
A6: Other Income | B6: ='HISTORICAL FINANCIALS'!B8 -> 3134 | C6: ='HISTORICAL FINANCIALS'!C8 -> 4018 | D6: ='HISTORICAL FINANCIALS'!D8 -> 3449 | E6: ='HISTORICAL FINANCIALS'!E8 -> 4422 | F6: ='HISTORICAL FINANCIALS'!F8 -> 3962
A7: Total Revenue | B7: ='HISTORICAL FINANCIALS'!B9 -> 167311 | C7: ='HISTORICAL FINANCIALS'!C9 -> 195772 | D7: ='HISTORICAL FINANCIALS'!D9 -> 228907 | E7: ='HISTORICAL FINANCIALS'!E9 -> 245315 | F7: ='HISTORICAL FINANCIALS'!F9 -> 259286
A8: Total Revenue Growth % | B8: — | C8: =C7/B7-1 -> 0.17010836 | D8: =D7/C7-1 -> 0.16925301 | E8: =E7/D7-1 -> 0.071679765 | F8: =F7/E7-1 -> 0.056951267
A10: EXPENSE ANALYSIS
A11: Particulars | B11: FY2021 | C11: FY2022 | D11: FY2023 | E11: FY2024 | F11: FY2025
A12: ='HISTORICAL FINANCIALS'!A11 -> employee benefit expense | B12: ='HISTORICAL FINANCIALS'!B11 -> 91814 | C12: ='HISTORICAL FINANCIALS'!C11 -> 107554 | D12: ='HISTORICAL FINANCIALS'!D11 -> 127522 | E12: ='HISTORICAL FINANCIALS'!E11 -> 140131 | F12: ='HISTORICAL FINANCIALS'!F11 -> 145788
A13: % of Revenue | B13: =B12/B4 -> 0.5592379 | C13: =C12/C4 -> 0.56089573 | D13: =D12/D4 -> 0.56561311 | E13: =E12/E4 -> 0.5817147 | F13: =F12/F4 -> 0.57099215
A14: ='HISTORICAL FINANCIALS'!A12 -> Cost of Equipment & Software Licences | B14: ='HISTORICAL FINANCIALS'!B12 -> 1462 | C14: ='HISTORICAL FINANCIALS'!C12 -> 1163 | D14: ='HISTORICAL FINANCIALS'!D12 -> 1881 | E14: ='HISTORICAL FINANCIALS'!E12 -> 3702 | F14: ='HISTORICAL FINANCIALS'!F12 -> 11648
A15: % of Revenue | B15: =B14/B4 -> 0.0089050232 | C15: =C14/C4 -> 0.0060650625 | D15: =D14/D4 -> 0.0083430173 | E15: =E14/E4 -> 0.015367819 | F15: =F14/F4 -> 0.045620467
A16: ='HISTORICAL FINANCIALS'!A13 -> finance costs | B16: ='HISTORICAL FINANCIALS'!B13 -> 637 | C16: ='HISTORICAL FINANCIALS'!C13 -> 784 | D16: ='HISTORICAL FINANCIALS'!D13 -> 779 | E16: ='HISTORICAL FINANCIALS'!E13 -> 778 | F16: ='HISTORICAL FINANCIALS'!F13 -> 796
A17: % of Revenue | B17: =B16/B4 -> 0.0038799588 | C17: =C16/C4 -> 0.0040885718 | D17: =D16/D4 -> 0.003455189 | E17: =E16/E4 -> 0.0032296497 | F17: =F16/F4 -> 0.0031176074
A18: ='HISTORICAL FINANCIALS'!A14 -> depreciation&amortization | B18: ='HISTORICAL FINANCIALS'!B14 -> 4065 | C18: ='HISTORICAL FINANCIALS'!C14 -> 4604 | D18: ='HISTORICAL FINANCIALS'!D14 -> 5022 | E18: ='HISTORICAL FINANCIALS'!E14 -> 4985 | F18: ='HISTORICAL FINANCIALS'!F14 -> 5242
A19: % of Revenue | B19: =B18/B4 -> 0.024759863 | C19: =C18/C4 -> 0.024009929 | D19: =D18/D4 -> 0.022274659 | E19: =E18/E4 -> 0.020693835 | F19: =F18/F4 -> 0.020530777
A20: ='HISTORICAL FINANCIALS'!A15 -> other operating expenses | B20: ='HISTORICAL FINANCIALS'!B15 -> 24355 | C20: ='HISTORICAL FINANCIALS'!C15 -> 29980 | D20: ='HISTORICAL FINANCIALS'!D15 -> 36796 | E20: ='HISTORICAL FINANCIALS'!E15 -> 32764 | F20: ='HISTORICAL FINANCIALS'!F15 -> 30481
A21: % of Revenue | B21: =B20/B4 -> 0.14834599 | C21: =C20/C4 -> 0.15634615 | D21: =D20/D4 -> 0.16320556 | E21: =E20/E4 -> 0.13601059 | F21: =F20/F4 -> 0.11938165
A22: Total Expenses | B22: ='HISTORICAL FINANCIALS'!B16 -> 122333 | C22: ='HISTORICAL FINANCIALS'!C16 -> 144085 | D22: ='HISTORICAL FINANCIALS'!D16 -> 172000 | E22: ='HISTORICAL FINANCIALS'!E16 -> 182360 | F22: ='HISTORICAL FINANCIALS'!F16 -> 193955
A23: % of Revenue | B23: =B22/B4 -> 0.74512873 | C23: =C22/C4 -> 0.75140545 | D23: =D22/D4 -> 0.76289154 | E23: =E22/E4 -> 0.7570166 | F23: =F22/F4 -> 0.75964265
A24: Tax rates | B24: ='HISTORICAL FINANCIALS'!B21/'HISTORICAL FINANCIALS'!B20 -> 0.2558958 | C24: ='HISTORICAL FINANCIALS'!C21/'HISTORICAL FINANCIALS'!C20 -> 0.25611856 | D24: ='HISTORICAL FINANCIALS'!D21/'HISTORICAL FINANCIALS'!D20 -> 0.25662924 | E24: ='HISTORICAL FINANCIALS'!E21/'HISTORICAL FINANCIALS'!E20 -> 0.25643176 | F24: ='HISTORICAL FINANCIALS'!F21/'HISTORICAL FINANCIALS'!F20 -> 0.25308047
A26: PROFITABILITY ANALYSIS
A27: Particulars | B27: FY2021 | C27: FY2022 | D27: FY2023 | E27: FY2024 | F27: FY2025
A28: ='HISTORICAL FINANCIALS'!A18 -> Profit Before Exceptional Item and Tax | B28: ='HISTORICAL FINANCIALS'!B18 -> 44978 | C28: ='HISTORICAL FINANCIALS'!C18 -> 51687 | D28: ='HISTORICAL FINANCIALS'!D18 -> 56907 | E28: ='HISTORICAL FINANCIALS'!E18 -> 62955 | F28: ='HISTORICAL FINANCIALS'!F18 -> 65331
A29: ='HISTORICAL FINANCIALS'!A19 -> Exceptional Item | B29: ='HISTORICAL FINANCIALS'!B19 -> 1218 | C29: ='HISTORICAL FINANCIALS'!C19 -> 0 | D29: ='HISTORICAL FINANCIALS'!D19 -> 0 | E29: ='HISTORICAL FINANCIALS'!E19 -> 958 | F29: ='HISTORICAL FINANCIALS'!F19 -> 0
A30: EBIT | B30: =B31+B16 -> 44397 | C30: =C31+C16 -> 52471 | D30: =D31+D16 -> 57686 | E30: =E31+E16 -> 62775 | F30: =F31+F16 -> 66127
A31: Profit Before Tax | B31: ='HISTORICAL FINANCIALS'!B20 -> 43760 | C31: ='HISTORICAL FINANCIALS'!C20 -> 51687 | D31: ='HISTORICAL FINANCIALS'!D20 -> 56907 | E31: ='HISTORICAL FINANCIALS'!E20 -> 61997 | F31: ='HISTORICAL FINANCIALS'!F20 -> 65331
A32: ='HISTORICAL FINANCIALS'!A21 -> Tax Expense | B32: ='HISTORICAL FINANCIALS'!B21 -> 11198 | C32: ='HISTORICAL FINANCIALS'!C21 -> 13238 | D32: ='HISTORICAL FINANCIALS'!D21 -> 14604 | E32: ='HISTORICAL FINANCIALS'!E21 -> 15898 | F32: ='HISTORICAL FINANCIALS'!F21 -> 16534
A33: Net Profit (Profit for the Year) | B33: ='HISTORICAL FINANCIALS'!B22 -> 32562 | C33: ='HISTORICAL FINANCIALS'!C22 -> 38449 | D33: ='HISTORICAL FINANCIALS'!D22 -> 42303 | E33: ='HISTORICAL FINANCIALS'!E22 -> 46099 | F33: ='HISTORICAL FINANCIALS'!F22 -> 48797
A34: EBIT Margin % | B34: =B30/B4 -> 0.27042156 | C34: =C30/C4 -> 0.27363706 | D34: =D30/D4 -> 0.2558614 | E34: =E30/E4 -> 0.26059288 | F34: =F30/F4 -> 0.2589925
A35: PBT Margin % | B35: =B31/B4 -> 0.2665416 | C35: =C31/C4 -> 0.26954848 | D35: =D31/D4 -> 0.25240621 | E35: =E31/E4 -> 0.25736323 | F35: =F31/F4 -> 0.25587489
A36: Net Profit Margin % | B36: =B33/B4 -> 0.19833472 | C36: =C33/C4 -> 0.20051211 | D36: =D33/D4 -> 0.1876314 | E36: =E33/E4 -> 0.19136712 | F36: =F33/F4 -> 0.19111795
A38: BALANCE SHEET ANALYSIS
A39: Particulars | B39: FY2021 | C39: FY2022 | D39: FY2023 | E39: FY2024 | F39: FY2025
A40: Total Assets | B40: ='HISTORICAL FINANCIALS'!B130 -> 130759 | C40: ='HISTORICAL FINANCIALS'!C130 -> 141514 | D40: ='HISTORICAL FINANCIALS'!D130 -> 143651 | E40: ='HISTORICAL FINANCIALS'!E130 -> 146449 | F40: ='HISTORICAL FINANCIALS'!F130 -> 159629
A41: Total Equity | B41: ='HISTORICAL FINANCIALS'!B136 -> 87108 | C41: ='HISTORICAL FINANCIALS'!C136 -> 89846 | D41: ='HISTORICAL FINANCIALS'!D136 -> 91206 | E41: ='HISTORICAL FINANCIALS'!E136 -> 91319 | F41: ='HISTORICAL FINANCIALS'!F136 -> 95771
A42: Total Liabilities | B42: =SUM('HISTORICAL FINANCIALS'!B145,'HISTORICAL FINANCIALS'!B156) -> 43651 | C42: =SUM('HISTORICAL FINANCIALS'!C145,'HISTORICAL FINANCIALS'!C156) -> 51668 | D42: =SUM('HISTORICAL FINANCIALS'!D145,'HISTORICAL FINANCIALS'!D156) -> 52445 | E42: =SUM('HISTORICAL FINANCIALS'!E145,'HISTORICAL FINANCIALS'!E156) -> 55130 | F42: =SUM('HISTORICAL FINANCIALS'!F145,'HISTORICAL FINANCIALS'!F156) -> 63858
A43: Cash & Cash Equivalents | B43: ='HISTORICAL FINANCIALS'!B123 -> 6858 | C43: ='HISTORICAL FINANCIALS'!C123 -> 12488 | D43: ='HISTORICAL FINANCIALS'!D123 -> 7123 | E43: ='HISTORICAL FINANCIALS'!E123 -> 9016 | F43: ='HISTORICAL FINANCIALS'!F123 -> 8342
...

Sheet ASSUMPTIONS & METHODOLOGY
A1: ASSUMPTIONS & METHODOLOGY
A2: Area | B2: Methodology / Assumption | C2: Reason
A3: Financial Statement Basis | B3: The analysis is based on TCS's consolidated financial statements for FY2021 to FY2025. | C3: The consolidated statements provide a consistent basis for analysing the company's overall financial performance across the five-year period.
A4: Currency & Units | B4: All financial statement amounts are presented in ₹ crore, as reported in the financial statements. | C4: Using the same unit throughout the model keeps the analysis consistent and avoids unnecessary conversion.
A5: Revenue | B5: Revenue from Operations is used as the primary revenue measure for margin, growth and efficiency calculations. | C5: Revenue from Operations represents the company's core operating revenue and is more useful for analysing operating performance.
A6: Total Revenue | B6: Total Revenue is calculated using Revenue from Operations plus Other Income. | C6: This provides a broader view of the company's total income while keeping operating revenue separately identifiable.
A7: Revenue Growth | B7: Year-over-year growth is calculated by comparing the current year's figure with the previous year's figure. | C7: This shows how quickly the company's revenue has changed from one year to the next.
A8: Expense Analysis | B8: Major expense categories are analysed individually and also expressed as a percentage of Revenue from Operations. | C8: This helps identify which costs have the greatest impact on revenue and how the cost structure has changed over time.
A9: EBIT | B9: EBIT is determined using Profit Before Tax plus Finance Costs. | C9: This isolates operating earnings before the effect of financing costs and tax.
A10: EBIT Margin | B10: EBIT is divided by Revenue from Operations. | C10: This shows the proportion of operating revenue retained as earnings before financing costs and tax.
A11: PBT Margin | B11: Profit Before Tax is divided by Revenue from Operations. | C11: This measures profitability before the effect of income tax.
A12: Net Profit Margin | B12: Profit for the Year is divided by Revenue from Operations. | C12: This shows how much profit the company retains from its operating revenue after expenses and tax.
A13: Exceptional Items | B13: Exceptional items are shown separately rather than being combined with normal operating results. | C13: Separating unusual items makes it easier to distinguish recurring performance from items that may not occur regularly.
... A39: Data Source & Scope | B39: The analysis and forecast are based on publicly available TCS annual reports and financial information used for this project. No confidential internal budgets, management forecasts, client-level data, contract-level information, or other non-public company data has been used. | C39: The purpose of the project is to demonstrate an FP&A approach using information that would be accessible to an external analyst. Where detailed internal operating drivers are not available, historical financial trends and clearly stated assumptions are used instead.

Sheet FORECAST ASSUMPTIONS
A1: FORECAST ASSUMPTIONS — FY 2026
A2: Assumption | B2: FY2025 Actual | C2: Historical Basis | D2: FY2026 Forecast | E2: Method / Driver
A3: Revenue Growth | B3: ='FINANCIAL ANALYSIS'!F5 -> 0.059906265 | C3: FY2022–FY2025 YoY Revenue from Operations growth | D3: =('FINANCIAL ANALYSIS'!F5+'FINANCIAL ANALYSIS'!E5)/2 -> 0.064183455 | E3: Average of FY2024–FY2025 growth; recent years selected as more representative of the current growth trend.
A4: Employee Benefit Expense % of Revenue | B4: ='FINANCIAL ANALYSIS'!F13 -> 0.57099215 | C4: FY2021–FY2025 expense-to-revenue trend | D4: =SUM('FINANCIAL ANALYSIS'!B13:F13)/5 -> 0.56769072 | E4: Five-year historical average; ratio remained relatively stable over the period.
A5: Equipment & Software % of Revenue | B5: ='FINANCIAL ANALYSIS'!F15 -> 0.045620467 | C5: FY2021–FY2025 expense-to-revenue trend | D5: =('FINANCIAL ANALYSIS'!E15+'FINANCIAL ANALYSIS'!F15)/2 -> 0.030494143 | E5: Average of FY2024–FY2025; recent period captures the significant increase while avoiding full reliance on the FY2025 level.
A6: Finance Cost % | B6: ='FINANCIAL ANALYSIS'!F17 -> 0.0031176074 | C6: FY2021–FY2025 finance cost as % of revenue | D6: =SUM('FINANCIAL ANALYSIS'!D17:F17)/3 -> 0.003267482 | E6: Average of FY2023–FY2025; recent period reflects the declining trend in finance costs.
A7: Depreciation & Amortization % of Revenue | B7: ='FINANCIAL ANALYSIS'!F19 -> 0.020530777 | C7: FY2021–FY2025 D&A as % of revenue | D7: ='FINANCIAL FORECAST'!C8/'FINANCIAL FORECAST'!C4 -> 0.020530777 | E7: FY2025 rate maintained; D&A has generally increased while declining as a percentage of Revenue.
A8: Other Operating Expenses % of Revenue | B8: ='FINANCIAL ANALYSIS'!F21 -> 0.11938165 | C8: FY2021–FY2025 expense-to-revenue trend | D8: =('FINANCIAL ANALYSIS'!E21+'FINANCIAL ANALYSIS'!F21)/2 -> 0.12769612 | E8: Average of FY2024–FY2025; recent period reflects the declining expense trend.
A9: Tax Rate | B9: ='FINANCIAL ANALYSIS'!F32/'FINANCIAL ANALYSIS'!F31 -> 0.25308047 | C9: FY2021–FY2025 effective tax rate | D9: =('FINANCIAL ANALYSIS'!B24+'FINANCIAL ANALYSIS'!C24+'FINANCIAL ANALYSIS'!D24+'FINANCIAL ANALYSIS'!E24+'FINANCIAL ANALYSIS'!F24)/5 -> 0.25563116 | E9: Five-year average of FY2021–FY2025 effective tax rates; historical rate remained stable.
A10: Receivable Days | B10: ='FINANCIAL ANALYSIS'!F54 -> 84.409574 | C10: FY2021–FY2025 receivable days trend | D10: =SUM('FINANCIAL ANALYSIS'!B54:F54)/5 -> 81.510586 | E10: Five-year average; receivable days remained stable throughout the period.
A11: Payable Days | B11: ='FINANCIAL ANALYSIS'!F55 -> 26.175066 | C11: FY2021–FY2025 payable days trend | D11: =SUM('FINANCIAL ANALYSIS'!B55:F55)/5 -> 22.459515 | E11: Five-year average; FY2025 increase not treated as a sustained trend.
A12: CapEx % of Revenue | B12: ='FINANCIAL ANALYSIS'!F63/'FINANCIAL ANALYSIS'!F4 -> -0.015121963 | C12: FY2021–FY2025 CapEx as % of Revenue | D12: =(('FINANCIAL ANALYSIS'!E63/'FINANCIAL ANALYSIS'!E4)+'FORECAST ASSUMPTIONS'!B12)/2 -> -0.013048895 | E12: Average of FY2024–FY2025 CapEx as % of Revenue; recent period reflects increased investment.
A13: U&DR % of Revenue | B13: ='FINANCIAL ANALYSIS'!F56 -> 0.015776034 | C13: FY2024–FY2025 U&DR as % of Revenue | D13: =('FINANCIAL ANALYSIS'!E56+'FINANCIAL ANALYSIS'!F56)/2 -> 0.015443238 | E13: Average of FY2024–FY2025 U&DR as % of Revenue; recent period reflects the current relationship with revenue.

Sheet FINANCIAL FORECAST
A1: FINANCIAL FORECAST -FY 2026
A2: Income Statement Forecast
A3: Particulars | B3: FY2025 Actual | C3: FY2026 Forecast
A4: Revenue from Operations | B4: ='FINANCIAL ANALYSIS'!F4 -> 255324 | C4: ='FINANCIAL ANALYSIS'!F4*1.0642 -> 271715.8
A5: Employee Benefit Expense | B5: ='HISTORICAL FINANCIALS'!F11 -> 145788 | C5: =C4*'FORECAST ASSUMPTIONS'!D4 -> 154250.54
A6: Equipment & Software | B6: ='FINANCIAL ANALYSIS'!F14 -> 11648 | C6: =C4*'FORECAST ASSUMPTIONS'!D5 -> 8285.7404
A7: Finance Cost | B7: ='FINANCIAL ANALYSIS'!F16 -> 796 | C7: =C4*'FORECAST ASSUMPTIONS'!D6 -> 887.8265
A8: D&A | B8: ='FINANCIAL ANALYSIS'!F18 -> 5242 | C8: =C4*'FORECAST ASSUMPTIONS'!B7 -> 5578.5364
A9: Other Operating Expenses | B9: ='FINANCIAL ANALYSIS'!F20 -> 30481 | C9: =C4*'FORECAST ASSUMPTIONS'!D8 -> 34697.054
A10: EBIT | B10: ='FINANCIAL ANALYSIS'!F30 -> 66127 | C10: =C11+C7 -> 68903.932
A11: PBT | B11: ='FINANCIAL ANALYSIS'!F31 -> 65331 | C11: =C4-(C5+C6+C7+C8+C9) -> 68016.106
A12: Tax expenses | B12: ='FINANCIAL ANALYSIS'!F32 -> 16534 | C12: =C11*'FORECAST ASSUMPTIONS'!D9 -> 17387.036
A13: net profit | B13: ='FINANCIAL ANALYSIS'!F33 -> 48797 | C13: =C11-C12 -> 50629.069
A15: Operating Working Capital Forecast
A16: Particulars | B16: FY2025 Actual | C16: FY2026 Forecast
A17: Trade Receivables | B17: ='FINANCIAL ANALYSIS'!F48+'FINANCIAL ANALYSIS'!F49 -> 59046 | C17: =C4*('FORECAST ASSUMPTIONS'!D10/365) -> 60678.669
A18: Trade Payables | B18: ='FINANCIAL ANALYSIS'!F50 -> 13909 | C18: =C4*('FORECAST ASSUMPTIONS'!D11/365) -> 16719.466
A19: ='FINANCIAL ANALYSIS'!A51 -> Unearned & Deferred Revenue | B19: ='FINANCIAL ANALYSIS'!F51 -> 4028 | C19: =C4*'FORECAST ASSUMPTIONS'!D13 -> 4196.1719
A20: Operating Working Capital | B20: =B17-B18-B19 -> 41109 | C20: =C17-C18-C19 -> 39763.032
A21: Change in Operating Working Capital | B21: __ | C21: =C20-B20 -> -1345.9685
A23: Cash Flow Forecast
A24: Particulars | B24: FY2025 Actual | C24: FY2026 Forecast
A25: Net Profit | B25: =B13 -> 48797 | C25: =C13 -> 50629.069
A26: Operating Cash Flow | B26: ='FINANCIAL ANALYSIS'!F60 -> 48908 | C26: =C25+C8-C21 -> 57553.574
A27: capex | B27: ='FINANCIAL ANALYSIS'!F63 -> -3861 | C27: =C4*'FORECAST ASSUMPTIONS'!D12 -> -3545.591
A28: Free Cash Flow | B28: ='FINANCIAL ANALYSIS'!F64 -> 45047 | C28: =C26+C27 -> 54007.983

Sheet Forecast Variance Analysis
A1: FORECAST VARIANCE ANALYSIS — FY2026
A2: Revenue
A3: Particulars | B3: FY2025 Actual | C3: FY2026 Forecast | D3: variance | E3: variance % | F3: F/U
A4: ='FINANCIAL FORECAST'!A4 -> Revenue from Operations | B4: ='FINANCIAL FORECAST'!B4 -> 255324 | C4: ='FINANCIAL FORECAST'!C4 -> 271715.8 | D4: =C4-B4 -> 16391.801 | E4: =D4/B4 -> 0.0642 | F4: =IF(D4>0,"F",IF(D4<0,"UF")) -> F
A6: Expense
A7: Particulars | B7: FY2025 Actual | C7: FY2026 Forecast | D7: variance | E7: variance % | F7: F/U
A8: ='FINANCIAL FORECAST'!A5 -> Employee Benefit Expense | B8: ='FINANCIAL FORECAST'!B5 -> 145788 | C8: ='FINANCIAL FORECAST'!C5 -> 154250.54 | D8: =B8-C8 -> -8462.538 | E8: =D8/B8 -> -0.058046876 | F8: =IF(D8>0,"F",IF(D8<0,"UF")) -> UF
A9: ='FINANCIAL FORECAST'!A6 -> Equipment & Software | B9: ='FINANCIAL FORECAST'!B6 -> 11648 | C9: ='FINANCIAL FORECAST'!C6 -> 8285.7404 | D9: =B9-C9 -> 3362.2596 | E9: =D9/B9 -> 0.28865553 | F9: =IF(D9>0,"F",IF(D9<0,"UF")) -> F
A10: ='FINANCIAL FORECAST'!A7 -> Finance Cost | B10: ='FINANCIAL FORECAST'!B7 -> 796 | C10: ='FINANCIAL FORECAST'!C7 -> 887.8265 | D10: =B10-C10 -> -91.826498 | E10: =D10/B10 -> -0.11535992 | F10: =IF(D10>0,"F",IF(D10<0,"UF")) -> UF
A11: ='FINANCIAL FORECAST'!A8 -> D&A | B11: ='FINANCIAL FORECAST'!B8 -> 5242 | C11: ='FINANCIAL FORECAST'!C8 -> 5578.5364 | D11: =B11-C11 -> -336.5364 | E11: =D11/B11 -> -0.0642 | F11: =IF(D11>0,"F",IF(D11<0,"UF")) -> UF
A12: ='FINANCIAL FORECAST'!A9 -> Other Operating Expenses | B12: ='FINANCIAL FORECAST'!B9 -> 30481 | C12: ='FINANCIAL FORECAST'!C9 -> 34697.054 | D12: =B12-C12 -> -4216.0538 | E12: =D12/B12 -> -0.13831744 | F12: =IF(D12>0,"F",IF(D12<0,"UF")) -> UF
A13: ='FINANCIAL FORECAST'!A12 -> Tax expenses | B13: ='FINANCIAL FORECAST'!B12 -> 16534 | C13: ='FINANCIAL FORECAST'!C12 -> 17387.036 | D13: =B13-C13 -> -853.0363 | E13: =D13/B13 -> -0.051592857 | F13: =IF(D13>0,"F",IF(D13<0,"UF")) -> UF
A15: Profitability
A16: Particulars | B16: FY2025 Actual | C16: FY2026 Forecast | D16: variance | E16: variance % | F16: F/U
A17: ='FINANCIAL FORECAST'!A10 -> EBIT | B17: ='FINANCIAL FORECAST'!B10 -> 66127 | C17: ='FINANCIAL FORECAST'!C10 -> 68903.932 | D17: =C17-B17 -> 2776.9322 | E17: =D17/B17 -> 0.041993924 | F17: =IF(D17>0,"F",IF(D17<0,"UF")) -> F
A18: ='FINANCIAL FORECAST'!A11 -> PBT | B18: ='FINANCIAL FORECAST'!B11 -> 65331 | C18: ='FINANCIAL FORECAST'!C11 -> 68016.106 | D18: =C18-B18 -> 2685.1057 | E18: =D18/B18 -> 0.041100024 | F18: =IF(D18>0,"F",IF(D18<0,"UF")) -> F
A19: ='FINANCIAL FORECAST'!A13 -> net profit | B19: ='FINANCIAL FORECAST'!B13 -> 48797 | C19: ='FINANCIAL FORECAST'!C13 -> 50629.069 | D19: =C19-B19 -> 1832.0694 | E19: =D19/B19 -> 0.037544714 | F19: =IF(D19>0,"F",IF(D19<0,"UF")) -> F
A21: Operating Working Capital
A22: Particulars | B22: FY2025 Actual | C22: FY2026 Forecast | D22: variance | E22: variance % | F22: F/U
A23: ='FINANCIAL FORECAST'!A17 -> Trade Receivables | B23: ='FINANCIAL FORECAST'!B17 -> 59046 | C23: ='FINANCIAL FORECAST'!C17 -> 60678.669 | D23: =B23-C23 -> -1632.6691 | E23: =D23/B23 -> -0.027650799 | F23: =IF(D23>0,"F",IF(D23<0,"UF")) -> UF
A24: ='FINANCIAL FORECAST'!A18 -> Trade Payables | B24: ='FINANCIAL FORECAST'!B18 -> 13909 | C24: ='FINANCIAL FORECAST'!C18 -> 16719.466 | D24: =C24-B24 -> 2810.4657 | E24: =D24/B24 -> 0.20206095 | F24: =IF(D24>0,"F",IF(D24<0,"UF")) -> F
A25: ='FINANCIAL FORECAST'!A19 -> Unearned & Deferred Revenue | B25: ='FINANCIAL FORECAST'!B19 -> 4028 | C25: ='FINANCIAL FORECAST'!C19 -> 4196.1719 | D25: =C25-B25 -> 168.17189 | E25: =D25/B25 -> 0.041750718 | F25: =IF(D25>0,"F",IF(D25<0,"UF")) -> F
A26: ='FINANCIAL FORECAST'!A20 -> Operating Working Capital | B26: ='FINANCIAL FORECAST'!B20 -> 41109 | C26: ='FINANCIAL FORECAST'!C20 -> 39763.032 | D26: =B26-C26 -> 1345.9685 | E26: =D26/B26 -> 0.032741455 | F26: =IF(D26>0,"F",IF(D26<0,"UF")) -> F
A28: Cash Flow
A29: Particulars | B29: FY2025 Actual | C29: FY2026 Forecast | D29: variance | E29: variance % | F29: F/U
A30: ='FINANCIAL FORECAST'!A26 -> Operating Cash Flow | B30: ='FINANCIAL FORECAST'!B26 -> 48908 | C30: ='FINANCIAL FORECAST'!C26 -> 57553.574 | D30: =C30-B30 -> 8645.5743 | E30: =D30/B30 -> 0.17677219 | F30: =IF(D30>0,"F",IF(D30<0,"UF")) -> F
A31: ='FINANCIAL FORECAST'!A27 -> capex | B31: ='FINANCIAL FORECAST'!B27 -> -3861 | C31: ='FINANCIAL FORECAST'!C27 -> -3545.591 | D31: =C31-B31 -> 315.40903 | E31: =315.41/3861 -> 0.081691272 | F31: =IF(D31>0,"F",IF(D31<0,"UF")) -> F
A32: ='FINANCIAL FORECAST'!A28 -> Free Cash Flow | B32: ='FINANCIAL FORECAST'!B28 -> 45047 | C32: ='FINANCIAL FORECAST'!C28 -> 54007.983 | D32: =C32-B32 -> 8960.9833 | E32: =D32/B32 -> 0.1989252 | F32: =IF(D32>0,"F",IF(D32<0,"UF")) -> F

Sheet Conclusions & Interpretations
A1: FY2026 Forecast – Management Insights
A2: Revenue Growth | B2: FY2026 revenue is expected to increase by 6.42% compared with FY2025. This shows that the company is expected to continue growing, although the growth is moderate.
A3: Profitability | B3: EBIT is expected to increase by 4.20%, while net profit is expected to increase by 3.75%. Profit is growing, but slightly slower than revenue, which suggests that expenses are putting some pressure on profitability.
A4: Receivables | B4: Trade receivables are expected to increase by 2.77%. This means more money may remain with customers at the end of the year. The company should keep an eye on collections to make sure customers are paying on time.
A5: Payables | B5: Trade payables are expected to increase by 20.21%. This helps the company's cash position because more payments to suppliers remain outstanding. However, the increase should be monitored to make sure it does not create problems with suppliers.
A6: Operating Working Capital | B6: Operating working capital is expected to decrease by ₹1,345.97 crore. This is positive for cash flow because less money will be tied up in day-to-day operations.
A7: Operating Cash Flow | B7: Operating cash flow is expected to increase by 17.68% to ₹57,553.57 crore. This shows that the company is expected to generate more cash from its normal operations.
A8: Free Cash Flow | B8: Free cash flow is expected to increase by 19.89% to ₹54,007.98 crore. This is a positive sign because the company is expected to have more cash available after spending on capital expenditure.
A9: Overall Interpretation | B9: Overall, the FY2026 forecast looks positive. Revenue and profit are expected to grow, while operating and free cash flow are expected to improve. The company has historically maintained strong liquidity, very low leverage and strong interest coverage. Although receivables are expected to increase, the overall operating working capital position improves and supports cash flow. The main areas to watch are the slight pressure on profit margins, customer collections and the increase in trade payables.
